<robot name="turtlebot" xmlns:xacro="http://ros.org/wiki/xacro">

  <!-- Base Link -->
  <link name="base_link">
    <inertial>
      <origin xyz="0.001453 -0.000453 0.029787" rpy="0 0 0"/>
      <mass value="2.234"/>
      <inertia ixx="0.05864" ixy="0.000124" ixz="0.000615" iyy="0.058786" iyz="1.4e-05" izz="1.53244"/>
    </inertial>
  </link>

  <!-- Left Wheel -->
  <link name="left_wheel"/>
  <joint name="left_wheel_joint" type="continuous">
    <parent link="base_link"/>
    <child link="left_wheel"/>
    <origin xyz="0 0.13 0.032" rpy="0 0 0"/>
    <axis xyz="0 1 0"/>
  </joint>

  <!-- Right Wheel -->
  <link name="right_wheel"/>
  <joint name="right_wheel_joint" type="continuous">
    <parent link="base_link"/>
    <child link="right_wheel"/>
    <origin xyz="0 -0.13 0.032" rpy="0 0 0"/>
    <axis xyz="0 1 0"/>
  </joint>

  <!-- Rack Link -->
  <link name="rack">
    <inertial>
      <origin xyz="0.001453 -0.000453 0.029787" rpy="0 0 0"/>
      <mass value="2.234"/>
      <inertia ixx="0.05864" ixy="0.000124" ixz="0.000615" iyy="0.058786" iyz="1.4e-05" izz="1.53244"/>
    </inertial>
  </link>
  <joint name="create_rack" type="fixed">
    <parent link="base_link"/>
    <child link="rack"/>
  </joint>

  <!-- Kinect Link -->
  <link name="kinect_link">
    <inertial>
      <origin xyz="0 0 0" rpy="0 0 0"/>
      <mass value="0.1"/>
      <inertia ixx="1" ixy="0" ixz="0" iyy="1" iyz="0" izz="1"/>
    </inertial>
  </link>
  <joint name="kinect_rack" type="fixed">
    <parent link="rack"/>
    <child link="kinect_link"/>
  </joint>

  <!-- Kinect Sensor (as Gazebo plugin) -->
  <gazebo reference="kinect_link">
    <sensor name="camera" type="depth">
      <update_rate>20</update_rate>
      <camera>
        <horizontal_fov>1.0472</horizontal_fov>
        <image>
          <width>640</width>
          <height>480</height>
          <format>R8G8B8</format>
        </image>
        <clip>
          <near>0.05</near>
          <far>3</far>
        </clip>
      </camera>
    </sensor>
  </gazebo>


  <!-- Gazebo plugin -->
  <gazebo>
    <plugin name="gazebo_base_controller" filename="libgazebo_ros_diff_drive.so">
      <odometry_frame>odom</odometry_frame>
      <commandTopic>cmd_vel</commandTopic>
      <publish_odom>true</publish_odom>
      <publish_odom_tf>true</publish_odom_tf>
      <left_wheel>left_wheel</left_wheel>
      <right_wheel>right_wheel</right_wheel>
      <wheel_separation>0.16</wheel_separation> <!-- Adjust if needed -->
      <wheel_diameter>0.055</wheel_diameter>    
      <command_topic>cmd-vel</command_topic>
      <odometry_topic>odom</odometry_topic>
      <odometry_frame>odom</odometry_frame>
      <robot_base_frame>base_link</robot_base_frame>
      <update_rate>50</update_rate>
    </plugin>
  </gazebo>

</robot>
